(dp1
S'output'
p2
S'<type \'exceptions.RuntimeError\'> Failure to connect, tried 5 times:\nTraceback (most recent call last):\n  File "/Users/joshuacheung/Documents/Projects/183_CS/183_project/gluon/packages/dal/pydal/base.py", line 454, in __init__\n    self._adapter = adapter(**kwargs)\n  File "/Users/joshuacheung/Documents/Projects/183_CS/183_project/gluon/packages/dal/pydal/adapters/__init__.py", line 40, in __call__\n    obj = super(AdapterMeta, cls).__call__(*args, **kwargs)\n  File "/Users/joshuacheung/Documents/Projects/183_CS/183_project/gluon/packages/dal/pydal/adapters/base.py", line 368, in __init__\n    super(SQLAdapter, self).__init__(*args, **kwargs)\n  File "/Users/joshuacheung/Documents/Projects/183_CS/183_project/gluon/packages/dal/pydal/adapters/base.py", line 52, in __init__\n    self.reconnect()\n  File "/Users/joshuacheung/Documents/Projects/183_CS/183_project/gluon/packages/dal/pydal/connection.py", line 152, in reconnect\n    self.connection = self.connector()\n  File "/Users/joshuacheung/Documents/Projects/183_CS/183_project/gluon/packages/dal/pydal/adapters/sqlite.py", line 42, in connector\n    return self.driver.Connection(self.dbpath, **self.driver_args)\nOperationalError: unable to open database file\n'
p3
sS'layer'
p4
S'/Users/joshuacheung/Documents/Projects/183_CS/183_project/applications/budget/models/db.py'
p5
sS'code'
p6
S'<code object <module> at 0x10ff0f3b0, file "/Users/joshuacheung/Documents/Projects/183_CS/183_project/applications/budget/models/db.py", line 6>'
p7
sS'snapshot'
p8
(dp9
sS'traceback'
p10
S'Traceback (most recent call last):\n  File "/Users/joshuacheung/Documents/Projects/183_CS/183_project/gluon/restricted.py", line 219, in restricted\n    exec(ccode, environment)\n  File "/Users/joshuacheung/Documents/Projects/183_CS/183_project/applications/budget/models/db.py", line 24, in <module>\n    check_reserved=[\'all\'])\n  File "/Users/joshuacheung/Documents/Projects/183_CS/183_project/gluon/packages/dal/pydal/base.py", line 169, in __call__\n    obj = super(MetaDAL, cls).__call__(*args, **kwargs)\n  File "/Users/joshuacheung/Documents/Projects/183_CS/183_project/gluon/packages/dal/pydal/base.py", line 474, in __init__\n    "Failure to connect, tried %d times:\\n%s" % (attempts, tb)\nRuntimeError: Failure to connect, tried 5 times:\nTraceback (most recent call last):\n  File "/Users/joshuacheung/Documents/Projects/183_CS/183_project/gluon/packages/dal/pydal/base.py", line 454, in __init__\n    self._adapter = adapter(**kwargs)\n  File "/Users/joshuacheung/Documents/Projects/183_CS/183_project/gluon/packages/dal/pydal/adapters/__init__.py", line 40, in __call__\n    obj = super(AdapterMeta, cls).__call__(*args, **kwargs)\n  File "/Users/joshuacheung/Documents/Projects/183_CS/183_project/gluon/packages/dal/pydal/adapters/base.py", line 368, in __init__\n    super(SQLAdapter, self).__init__(*args, **kwargs)\n  File "/Users/joshuacheung/Documents/Projects/183_CS/183_project/gluon/packages/dal/pydal/adapters/base.py", line 52, in __init__\n    self.reconnect()\n  File "/Users/joshuacheung/Documents/Projects/183_CS/183_project/gluon/packages/dal/pydal/connection.py", line 152, in reconnect\n    self.connection = self.connector()\n  File "/Users/joshuacheung/Documents/Projects/183_CS/183_project/gluon/packages/dal/pydal/adapters/sqlite.py", line 42, in connector\n    return self.driver.Connection(self.dbpath, **self.driver_args)\nOperationalError: unable to open database file\n\n'
p11
s.